<mujoco model="轮足狗机器人v3">
  <compiler angle="radian" meshdir="meshes"/>
  <option timestep="0.001" iterations="50" solver="PGS" gravity="0 0 -9.81">
    <flag frictionloss="enable" sensor="enable"/>
  </option>
  <worldbody>
    <light directional="true" diffuse="0.8 0.8 0.8" specular="0.3 0.3 0.3" pos="0 0 5" dir="0 0 -1" />
    <geom name="ground" type="plane" size="0 0 1" material="grid" condim="4" conaffinity="15" friction="1.0 0.5 0.5"/>
    <body name="trunk" pos="0 0 0.45">
      <joint name="root" type="free" />
      <inertial pos="-0.00111 0.00718 0.07632" mass="18.69147" fullinertia="0.24077 0.63159 0.58481 -0.00158 0.00277 -0.00895" />
      <site name="imu" pos="0 0 0" size="0.01"/>
      <!-- Front camera for person detection -->
      <camera name="front_camera" pos="0.35 0 0.15" xyaxes="0 -1 0 0 0 1" fovy="60"/>
      <geom size="0.205 0.129 0.0775" pos="0 0.00124 0.07541" type="box" rgba="0.752941 0.752941 0.752941 1" />
      <geom size="0.025 0.135 0.07" pos="0.23 0 0.07" type="box" rgba="0.752941 0.752941 0.752941 1" />
      <geom size="0.025 0.135 0.07" pos="-0.23 0 0.07" type="box" rgba="0.752941 0.752941 0.752941 1" />
      <geom size="0.08 0.06 0.072" pos="0.335 0 0.08" type="box" rgba="0.752941 0.752941 0.752941 1" />
      <geom size="0.0825 0.05 0.075" pos="-0.3375 0 0.08" type="box" rgba="0.752941 0.752941 0.752941 1" />
      <geom size="0.0384 0.0384 0.04005" pos="-0.29638 -0.0012453 0.1849" quat="-3.67321e-06 0 0 1" type="box" rgba="0.898039 0.917647 0.929412 1" />
      <body name="fr_hip_Link" pos="0.2395 -0.065 0.08065">
        <inertial pos="0.06964 -0.04836 0.00073" quat="0.625515 0.616922 0.338061 0.337421" mass="1.78126" diaginertia="0.0173549 0.0163714 0.00282375" />
        <joint name="fr_hip_joint" pos="0 0 0" axis="-1 0 0" range="-0.41 0.41"  class="leg_joint_param" actuatorfrcrange="-120 120"/>
        <geom size="0.06 0.024" pos="0.07752 -0.05564 0.00083" quat="0.707105 0.707108 0 0" type="cylinder" rgba="0.898039 0.917647 0.929412 1" />
        <body name="fr_thigh_Link" pos="0.078 -0.0795 0">
          <inertial pos="-0.19519 -0.02855 -0.01131" quat="0.4815 0.451865 0.516848 0.544833" mass="2.40982" diaginertia="0.12237 0.120515 0.00342445" />
          <joint name="fr_thigh_joint" pos="0 0 0" axis="0 1 0" range="-3.14 0"  class="leg_joint_param" actuatorfrcrange="-120 120"/>
          <geom size="0.064 0.015" pos="0 -0.0195 0" quat="0.707105 0.707108 0 0" type="cylinder" rgba="0.898039 0.917647 0.929412 1" />
          <geom size="0.09 0.015 0.03" pos="-0.125 -0.02059 -0.01001" quat="0.997888 0 -0.0649542 0" type="box" rgba="0.898039 0.917647 0.929412 1" />
          <geom size="0.0655 0.028" pos="-0.2485 -0.032 -0.0135" quat="0.707105 0.707108 0 0" type="cylinder" rgba="0.898039 0.917647 0.929412 1" />
          <body name="fr_calf_Link" pos="-0.24954 -0.057 -0.01515">
            <inertial pos="0.17266 -0.02895 0.04224" quat="0.582691 0.473615 0.397387 0.527488" mass="1.89384" diaginertia="0.0857582 0.0849173 0.0023945" />
            <joint name="fr_calf_joint" pos="0 0 0" axis="0 1 0" range="0 3.14"  class="leg_joint_param" actuatorfrcrange="-120 120"/>
            <geom size="0.0635 0.015" pos="0 -0.02653 0" quat="0.707105 0.707108 0 0" type="cylinder" rgba="0.898039 0.917647 0.929412 1" />
            <geom size="0.09 0.02 0.0225" pos="0.14 -0.02903 0.0305" quat="0.991445 0 -0.130526 0" type="box" rgba="0.898039 0.917647 0.929412 1" />
            <geom size="0.06 0.0275" pos="0.249 -0.02903 0.0531" quat="0.707105 0.707108 0 0" type="cylinder" rgba="0.898039 0.917647 0.929412 1" />
            <body name="fr_foot_Link" pos="0.24443 -0.061 0.0525">
              <inertial pos="0.00146 -0.01336 -0.00634" quat="0.713042 -0.0388899 0.00283165 0.700036" mass="0.32377" diaginertia="0.00122196 0.000719831 0.000708212" />
              <joint name="fr_foot_joint" limited="false" pos="0 0 0" axis="0 1 0"  class="leg_joint_param" actuatorfrcrange="-60 60"/>
              <geom size="0.12 0.028085" pos="0 -0.01631 0" quat="0.707105 0.707108 0 0" type="cylinder" rgba="0.898039 0.917647 0.929412 1" />
            </body>
          </body>
        </body>
      </body>
      <body name="fl_hip_Link" pos="0.2395 0.065 0.08065">
        <inertial pos="0.06964 0.04836 -0.00073" quat="0.338061 0.337421 0.625515 0.616922" mass="1.78126" diaginertia="0.0173549 0.0163714 0.00282375" />
        <joint name="fl_hip_joint" pos="0 0 0" axis="-1 0 0" range="-0.41 0.41"  class="leg_joint_param" actuatorfrcrange="-120 120"/>
        <geom size="0.06 0.024" pos="0.07752 0.05564 0.00083" quat="0.707105 0.707108 0 0" type="cylinder" rgba="0.898039 0.917647 0.929412 1" />
        <body name="fl_thigh_Link" pos="0.078 0.0795 0">
          <inertial pos="-0.19484 0.02855 -0.01176" quat="0.542469 0.519007 0.447927 0.48551" mass="2.40982" diaginertia="0.121966 0.120079 0.00347509" />
          <joint name="fl_thigh_joint" pos="0 0 0" axis="0 -1 0" range="0 3.14"  class="leg_joint_param" actuatorfrcrange="-120 120"/>
          <geom size="0.064 0.015" pos="0 0.0195 0" quat="0.707105 0.707108 0 0" type="cylinder" rgba="0.898039 0.917647 0.929412 1" />
          <geom size="0.09 0.015 0.03" pos="-0.125 0.02059 -0.01001" quat="0.997888 0 -0.0649542 0" type="box" rgba="0.898039 0.917647 0.929412 1" />
          <geom size="0.0655 0.028" pos="-0.2485 0.032 -0.0135" quat="0.707105 0.707108 0 0" type="cylinder" rgba="0.898039 0.917647 0.929412 1" />
          <body name="fl_calf_Link" pos="-0.24954 0.057 -0.01515">
            <inertial pos="0.17384 0.02895 0.03735" quat="0.52142 0.405052 0.481468 0.576405" mass="1.89384" diaginertia="0.0858075 0.0849699 0.00239256" />
            <joint name="fl_calf_joint" pos="0 0 0" axis="0 -1 0" range="-3.14 0"  class="leg_joint_param" actuatorfrcrange="-120 120"/>
            <geom size="0.0635 0.015" pos="0 0.02653 0" quat="0.707105 0.707108 0 0" type="cylinder" rgba="0.898039 0.917647 0.929412 1" />
            <geom size="0.09 0.02 0.0225" pos="0.14 0.02903 0.0305" quat="0.991445 0 -0.130526 0" type="box" rgba="0.898039 0.917647 0.929412 1" />
            <geom size="0.06 0.0275" pos="0.249 0.02903 0.0531" quat="0.707105 0.707108 0 0" type="cylinder" rgba="0.898039 0.917647 0.929412 1" />
            <body name="fl_foot_Link" pos="0.24443 0.061 0.0525">
              <inertial pos="0 0.01336 0" quat="0.707107 0 0 0.707107" mass="0.32377" diaginertia="0.00121 0.00071 0.00071" />
              <joint name="fl_foot_joint" limited="false" pos="0 0 0" axis="0 -1 0"  class="leg_joint_param" actuatorfrcrange="-60 60"/>
              <geom size="0.12 0.028085" pos="0 0.01631 0" quat="0.707105 0.707108 0 0" type="cylinder" rgba="0.898039 0.917647 0.929412 1" />
            </body>
          </body>
        </body>
      </body>
      <body name="rr_hip_Link" pos="-0.2395 -0.065 0.08065">
        <inertial pos="-0.06964 -0.04836 -0.00073" quat="0.337421 0.338061 0.616922 0.625515" mass="1.78126" diaginertia="0.0173549 0.0163714 0.00282375" />
        <joint name="rr_hip_joint" pos="0 0 0" axis="1 0 0" range="-0.41 0.41"  class="leg_joint_param" actuatorfrcrange="-120 120"/>
        <geom size="0.06 0.024" pos="-0.07752 -0.05564 0.00083" quat="0.707105 0.707108 0 0" type="cylinder" rgba="0.898039 0.917647 0.929412 1" />
        <body name="rr_thigh_Link" pos="-0.078 -0.0795 0">
          <inertial pos="0.19473 -0.02855 -0.01335" quat="0.51663 0.544751 0.487118 0.446157" mass="2.40982" diaginertia="0.121968 0.12008 0.00347229" />
          <joint name="rr_thigh_joint" pos="0 0 0" axis="0 1 0" range="0 3.14"  class="leg_joint_param" actuatorfrcrange="-120 120"/>
          <geom size="0.064 0.015" pos="0 -0.0195 0" quat="0.707105 0.707108 0 0" type="cylinder" rgba="0.898039 0.917647 0.929412 1" />
          <geom size="0.09 0.015 0.03" pos="0.125 -0.02059 -0.01001" quat="0.997888 0 0.0649542 0" type="box" rgba="0.898039 0.917647 0.929412 1" />
          <geom size="0.0655 0.028" pos="0.2485 -0.032 -0.0135" quat="0.707105 0.707108 0 0" type="cylinder" rgba="0.898039 0.917647 0.929412 1" />
          <body name="rr_calf_Link" pos="0.24954 -0.057 -0.01515">
            <inertial pos="-0.17353 -0.02895 0.03877" quat="0.401946 0.524283 0.577237 0.479963" mass="1.89384" diaginertia="0.0858076 0.0849665 0.00239596" />
            <joint name="rr_calf_joint" pos="0 0 0" axis="0 1 0" range="-6.28 0"  class="leg_joint_param" actuatorfrcrange="-120 120"/>
            <geom size="0.0635 0.015" pos="0 -0.02653 0" quat="0.707105 0.707108 0 0" type="cylinder" rgba="0.898039 0.917647 0.929412 1" />
            <geom size="0.09 0.02 0.0225" pos="-0.14 -0.02903 0.0305" quat="0.991445 0 0.130526 0" type="box" rgba="0.898039 0.917647 0.929412 1" />
            <geom size="0.06 0.0275" pos="-0.249 -0.02903 0.0531" quat="0.707105 0.707108 0 0" type="cylinder" rgba="0.898039 0.917647 0.929412 1" />
            <body name="rr_foot_Link" pos="-0.24443 -0.061 0.0525">
              <inertial pos="0 -0.01336 0" quat="0.707107 0 0 0.707107" mass="0.32377" diaginertia="0.00121 0.00071 0.00071" />
              <joint name="rr_foot_joint" limited="false" pos="0 0 0" axis="0 1 0"  class="leg_joint_param" actuatorfrcrange="-60 60"/>
              <geom size="0.12 0.028085" pos="0 -0.01631 0" quat="0.707105 0.707108 0 0" type="cylinder" rgba="0.898039 0.917647 0.929412 1" />
            </body>
          </body>
        </body>
      </body>
      <body name="rl_hip_Link" pos="-0.2395 0.065 0.08065">
        <inertial pos="-0.0696 0.04836 0.00075" quat="0.616925 0.625523 0.337421 0.338041" mass="1.78126" diaginertia="0.0173387 0.0163514 0.00282991" />
        <joint name="rl_hip_joint" pos="0 0 0" axis="1 0 0" range="-0.41 0.41"  class="leg_joint_param" actuatorfrcrange="-120 120"/>
        <geom size="0.06 0.024" pos="-0.07752 0.05564 0.00083" quat="0.707105 0.707108 0 0" type="cylinder" rgba="0.898039 0.917647 0.929412 1" />
        <body name="rl_thigh_Link" pos="-0.078 0.0795 0">
          <inertial pos="0.19519 0.02855 -0.01131" quat="0.451865 0.4815 0.544833 0.516848" mass="2.40982" diaginertia="0.12237 0.120515 0.00342445" />
          <joint name="rl_thigh_joint" pos="0 0 0" axis="0 -1 0" range="-3.14 0"  class="leg_joint_param" actuatorfrcrange="-120 120"/>
          <geom size="0.064 0.015" pos="0 0.0195 0" quat="0.707105 0.707108 0 0" type="cylinder" rgba="0.898039 0.917647 0.929412 1" />
          <geom size="0.09 0.015 0.03" pos="0.125 0.02059 -0.01001" quat="0.997888 0 0.0649542 0" type="box" rgba="0.898039 0.917647 0.929412 1" />
          <geom size="0.0655 0.028" pos="0.2485 0.032 -0.0135" quat="0.707105 0.707108 0 0" type="cylinder" rgba="0.898039 0.917647 0.929412 1" />
          <body name="rl_calf_Link" pos="0.24954 0.057 -0.01515">
            <inertial pos="-0.17385 0.02895 0.03733" quat="0.478974 0.57966 0.517737 0.408077" mass="1.89384" diaginertia="0.0858096 0.0849658 0.00239458" />
            <joint name="rl_calf_joint" pos="0 0 0" axis="0 -1 0" range="0 6.28"  class="leg_joint_param" actuatorfrcrange="-120 120"/>
            <geom size="0.0635 0.015" pos="0 0.02653 0" quat="0.707105 0.707108 0 0" type="cylinder" rgba="0.898039 0.917647 0.929412 1" />
            <geom size="0.09 0.02 0.0225" pos="-0.14 0.02903 0.0305" quat="0.991445 0 0.130526 0" type="box" rgba="0.898039 0.917647 0.929412 1" />
            <geom size="0.06 0.0275" pos="-0.249 0.02903 0.0531" quat="0.707105 0.707108 0 0" type="cylinder" rgba="0.898039 0.917647 0.929412 1" />
            <body name="rl_foot_Link" pos="-0.24443 0.061 0.0525">
              <inertial pos="0 0.01336 0" quat="0.707107 0 0 0.707107" mass="0.32377" diaginertia="0.00121 0.00071 0.00071" />
              <joint name="rl_foot_joint" limited="false" pos="0 0 0" axis="0 -1 0"  class="leg_joint_param" actuatorfrcrange="-60 60"/>
              <geom size="0.12 0.028085" pos="0 0.01631 0" quat="0.707105 0.707108 0 0" type="cylinder" rgba="0.898039 0.917647 0.929412 1" />
            </body>
          </body>
        </body>
      </body>
    </body>
  
    <!-- === SCENE === -->

    <!-- ==================== LIGHTING ==================== -->
    <!-- Room lights (one per room) -->
    <light name="light_living" pos="3 2.5 2.7" dir="0 0 -1" diffuse="0.55 0.50 0.42" cutoff="65"/>
    <light name="light_dining" pos="3 7.5 2.7" dir="0 0 -1" diffuse="0.55 0.50 0.42" cutoff="65"/>
    <light name="light_kitchen" pos="17 2.5 2.7" dir="0 0 -1" diffuse="0.60 0.58 0.52" cutoff="65"/>
    <light name="light_study" pos="17 7.5 2.7" dir="0 0 -1" diffuse="0.55 0.52 0.45" cutoff="65"/>
    <light name="light_hall_a" pos="10 3 2.7" dir="0 0 -1" diffuse="0.50 0.48 0.42" cutoff="55"/>
    <light name="light_hall_b" pos="10 7 2.7" dir="0 0 -1" diffuse="0.50 0.48 0.42" cutoff="55"/>
    <light name="light_master" pos="3.5 12 2.7" dir="0 0 -1" diffuse="0.50 0.45 0.38" cutoff="60"/>
    <light name="light_guest" pos="16 12 2.7" dir="0 0 -1" diffuse="0.50 0.45 0.38" cutoff="60"/>
    <light name="light_bath" pos="8.5 12 2.7" dir="0 0 -1" diffuse="0.55 0.55 0.55" cutoff="55"/>
    <!-- Global ambient fill -->
    <light name="sun" pos="10 7 4" dir="0 0 -1" directional="true" diffuse="0.25 0.25 0.25"/>

    <!-- ==================== FLOORS ==================== -->
    <!-- Floor: plane for physics contact (correct collision) + box for mj_ray detection -->
    <geom name="floor" type="plane" pos="10 7 0" size="10.5 7.5 0.05" material="marble_mat"/>
    <geom name="floor_raycast" type="box" pos="10 7 -0.02" size="10.5 7.5 0.01"
          contype="0" conaffinity="0" group="3" rgba="0 0 0 0"/>
    <!-- Ceiling: needed for downward-facing lidar rays -->
    <geom name="ceiling" type="box" pos="10 7 2.85" size="10.5 7.5 0.05" material="wall_mat"
          contype="0" conaffinity="0" group="3"/>

    <!-- Per-room floor overlays (visual only) -->
    <geom name="f_living" type="box" pos="3 2.5 0.001" size="3 2.5 0.001" material="wood_mat" contype="0" conaffinity="0"/>
    <geom name="f_dining" type="box" pos="3 7.5 0.001" size="3 2.5 0.001" material="wood_mat" contype="0" conaffinity="0"/>
    <geom name="f_kitchen" type="box" pos="17 2.5 0.001" size="3 2.5 0.001" material="tile_mat" contype="0" conaffinity="0"/>
    <geom name="f_study" type="box" pos="17 7.5 0.001" size="3 2.5 0.001" material="wood_mat" contype="0" conaffinity="0"/>
    <geom name="f_master" type="box" pos="3.5 12 0.001" size="3.5 2 0.001" material="carpet_mat" contype="0" conaffinity="0"/>
    <geom name="f_guest" type="box" pos="16 12 0.001" size="4 2 0.001" material="carpet_mat" contype="0" conaffinity="0"/>
    <geom name="f_bath" type="box" pos="8.5 12 0.001" size="1.5 2 0.001" material="bath_tile" contype="0" conaffinity="0"/>

    <!-- ==================== EXTERIOR WALLS ==================== -->
    <!-- height=2.8m, thickness=0.1m -->
    <geom name="ew_south" type="box" pos="10 -0.05 1.4" size="10.1 0.05 1.4" material="wall_mat"/>
    <geom name="ew_north" type="box" pos="10 14.05 1.4" size="10.1 0.05 1.4" material="wall_mat"/>
    <geom name="ew_west" type="box" pos="-0.05 7 1.4" size="0.05 7.1 1.4" material="wall_mat"/>
    <geom name="ew_east" type="box" pos="20.05 7 1.4" size="0.05 7.1 1.4" material="wall_mat"/>

    <!-- ==================== INTERIOR WALLS ==================== -->

    <!-- LEFT WALL (x=6): Living/Dining ↔ Central Hall -->
    <!-- y=0 to y=2.4 -->
    <geom name="iw_l1" type="box" pos="6 1.2 1.4" size="0.05 1.2 1.4" material="accent_wall"/>
    <!-- y=3.6 to y=5 (gap at 2.4..3.6 = door to Living) -->
    <geom name="iw_l2" type="box" pos="6 4.3 1.4" size="0.05 0.7 1.4" material="accent_wall"/>
    <!-- y=5 to y=7.4 -->
    <geom name="iw_l3" type="box" pos="6 6.2 1.4" size="0.05 1.2 1.4" material="accent_wall"/>
    <!-- y=8.6 to y=10 (gap at 7.4..8.6 = door to Dining) -->
    <geom name="iw_l4" type="box" pos="6 9.3 1.4" size="0.05 0.7 1.4" material="accent_wall"/>

    <!-- RIGHT WALL (x=14): Central Hall ↔ Kitchen/Study -->
    <!-- y=0 to y=2.4 -->
    <geom name="iw_r1" type="box" pos="14 1.2 1.4" size="0.05 1.2 1.4" material="accent_wall"/>
    <!-- y=3.6 to y=5 (gap at 2.4..3.6 = door to Kitchen) -->
    <geom name="iw_r2" type="box" pos="14 4.3 1.4" size="0.05 0.7 1.4" material="accent_wall"/>
    <!-- y=5 to y=7.4 -->
    <geom name="iw_r3" type="box" pos="14 6.2 1.4" size="0.05 1.2 1.4" material="accent_wall"/>
    <!-- y=8.6 to y=10 (gap at 7.4..8.6 = door to Study) -->
    <geom name="iw_r4" type="box" pos="14 9.3 1.4" size="0.05 0.7 1.4" material="accent_wall"/>

    <!-- LIVING/DINING DIVIDER (y=5, x=0..6): door at x=2.4..3.6 -->
    <geom name="iw_ld1" type="box" pos="1.2 5 1.4" size="1.2 0.05 1.4" material="accent_wall"/>
    <geom name="iw_ld2" type="box" pos="4.8 5 1.4" size="1.2 0.05 1.4" material="accent_wall"/>

    <!-- KITCHEN/STUDY DIVIDER (y=5, x=14..20): door at x=16.4..17.6 -->
    <geom name="iw_ks1" type="box" pos="15.2 5 1.4" size="1.2 0.05 1.4" material="accent_wall"/>
    <geom name="iw_ks2" type="box" pos="18.8 5 1.4" size="1.2 0.05 1.4" material="accent_wall"/>

    <!-- BEDROOM WALL (y=10, full width): doors at multiple points -->
    <!-- x=0 to x=2.4 -->
    <geom name="iw_b1" type="box" pos="1.2 10 1.4" size="1.2 0.05 1.4" material="wall_mat"/>
    <!-- x=3.6 to x=6 (gap = door to Master BR) -->
    <geom name="iw_b2" type="box" pos="4.8 10 1.4" size="1.2 0.05 1.4" material="wall_mat"/>
    <!-- x=6 to x=7.9 -->
    <geom name="iw_b3" type="box" pos="6.95 10 1.4" size="0.95 0.05 1.4" material="wall_mat"/>
    <!-- x=9.1 to x=11.4 (gap at 7.9..9.1 = door to Bathroom) -->
    <geom name="iw_b4" type="box" pos="10.25 10 1.4" size="1.15 0.05 1.4" material="wall_mat"/>
    <!-- x=12.6 to x=14 (gap at 11.4..12.6 = door to Guest BR) -->
    <geom name="iw_b5" type="box" pos="13.3 10 1.4" size="0.7 0.05 1.4" material="wall_mat"/>
    <!-- x=14 to x=15.4 -->
    <geom name="iw_b6" type="box" pos="14.7 10 1.4" size="0.7 0.05 1.4" material="wall_mat"/>
    <!-- x=16.6 to x=20 (gap at 15.4..16.6 = another door to Guest) -->
    <geom name="iw_b7" type="box" pos="18.3 10 1.4" size="1.7 0.05 1.4" material="wall_mat"/>

    <!-- BATHROOM walls (x=7, x=10, y=10..14) -->
    <geom name="iw_bath_w" type="box" pos="7 12 1.4" size="0.05 2.05 1.4" material="wall_mat"/>
    <geom name="iw_bath_e" type="box" pos="10 12 1.4" size="0.05 2.05 1.4" material="wall_mat"/>

    <!-- LAUNDRY nook (x=10..12, y=10..14) — open niche, just east wall -->
    <geom name="iw_laund_e" type="box" pos="12 12 1.4" size="0.05 2.05 1.4" material="wall_mat"/>


    <!-- ==================== LIVING ROOM (x=0..6, y=0..5) ==================== -->

    <!-- L-sofa against south-west -->
    <body name="sofa_main" pos="1.8 1.0 0">
      <geom type="box" pos="0 0 0.18" size="1.2 0.38 0.18" material="sofa_blue"/>
      <geom type="box" pos="0 -0.08 0.42" size="1.15 0.30 0.06" material="sofa_blue"/>
      <geom type="box" pos="0 0.30 0.48" size="1.15 0.06 0.28" material="sofa_blue"/>
      <geom type="box" pos="-1.15 0 0.38" size="0.05 0.38 0.16" material="sofa_blue"/>
      <geom type="box" pos="1.15 0 0.38" size="0.05 0.38 0.16" material="sofa_blue"/>
      <!-- Throw pillows -->
      <geom type="box" pos="-0.7 -0.1 0.52" size="0.15 0.12 0.08" material="cushion_mat"/>
      <geom type="box" pos="0.7 -0.1 0.52" size="0.15 0.12 0.08" material="cushion_mat"/>
    </body>

    <!-- Coffee table -->
    <body name="coffee_tbl" pos="1.8 2.3 0">
      <geom type="cylinder" pos="-0.35 -0.2 0.18" size="0.02 0.18" material="dark_wood"/>
      <geom type="cylinder" pos="0.35 -0.2 0.18" size="0.02 0.18" material="dark_wood"/>
      <geom type="cylinder" pos="-0.35 0.2 0.18" size="0.02 0.18" material="dark_wood"/>
      <geom type="cylinder" pos="0.35 0.2 0.18" size="0.02 0.18" material="dark_wood"/>
      <geom type="box" pos="0 0 0.37" size="0.45 0.25 0.02" material="dark_wood"/>
    </body>

    <!-- TV + media console against west wall -->
    <body name="tv_console" pos="0.25 3.5 0">
      <geom type="box" pos="0 0 0.22" size="0.22 0.8 0.22" material="dark_wood"/>
      <geom type="box" pos="0 0 0.45" size="0.22 0.8 0.01" material="dark_wood"/>
      <geom name="tv" type="box" pos="0.02 0 0.78" size="0.025 0.65 0.4" material="black_mat"/>
    </body>

    <!-- Floor lamp -->
    <body name="lamp_living" pos="0.4 0.5 0">
      <geom type="cylinder" pos="0 0 0.02" size="0.12 0.02" material="lamp_base"/>
      <geom type="cylinder" pos="0 0 0.7" size="0.015 0.68" material="lamp_base"/>
      <geom type="cylinder" pos="0 0 1.38" size="0.12 0.12" material="lamp_shade" contype="0" conaffinity="0"/>
    </body>

    <!-- Rug -->
    <geom name="rug_living" type="box" pos="2.0 2.0 0.004" size="1.5 1.2 0.004"
          material="rug_red" contype="0" conaffinity="0"/>

    <!-- Wall art -->
    <geom name="art_living" type="box" pos="0.02 2.5 1.5" size="0.02 0.4 0.3"
          material="painting_mat" contype="0" conaffinity="0"/>


    <!-- ==================== DINING ROOM (x=0..6, y=5..10) ==================== -->

    <!-- Dining table (large, 8-seater) -->
    <body name="dining_table" pos="3 7.5 0">
      <geom type="cylinder" pos="-0.65 -0.4 0.36" size="0.035 0.36" material="oak_mat"/>
      <geom type="cylinder" pos="0.65 -0.4 0.36" size="0.035 0.36" material="oak_mat"/>
      <geom type="cylinder" pos="-0.65 0.4 0.36" size="0.035 0.36" material="oak_mat"/>
      <geom type="cylinder" pos="0.65 0.4 0.36" size="0.035 0.36" material="oak_mat"/>
      <geom type="box" pos="0 0 0.73" size="0.8 0.5 0.025" material="oak_mat"/>
    </body>

    <!-- 4 dining chairs -->
    <body name="dchair1" pos="2.0 7.5 0">
      <geom type="box" pos="0 0 0.23" size="0.17 0.17 0.23" material="light_wood" contype="0" conaffinity="0"/>
      <geom type="box" pos="0 0 0.46" size="0.19 0.19 0.015" material="light_wood"/>
      <geom type="box" pos="0 0.17 0.66" size="0.17 0.015 0.19" material="light_wood"/>
    </body>
    <body name="dchair2" pos="4.0 7.5 0">
      <geom type="box" pos="0 0 0.23" size="0.17 0.17 0.23" material="light_wood" contype="0" conaffinity="0"/>
      <geom type="box" pos="0 0 0.46" size="0.19 0.19 0.015" material="light_wood"/>
      <geom type="box" pos="0 -0.17 0.66" size="0.17 0.015 0.19" material="light_wood"/>
    </body>
    <body name="dchair3" pos="3.0 6.7 0">
      <geom type="box" pos="0 0 0.23" size="0.17 0.17 0.23" material="light_wood" contype="0" conaffinity="0"/>
      <geom type="box" pos="0 0 0.46" size="0.19 0.19 0.015" material="light_wood"/>
      <geom type="box" pos="0 0.17 0.66" size="0.17 0.015 0.19" material="light_wood"/>
    </body>
    <body name="dchair4" pos="3.0 8.3 0">
      <geom type="box" pos="0 0 0.23" size="0.17 0.17 0.23" material="light_wood" contype="0" conaffinity="0"/>
      <geom type="box" pos="0 0 0.46" size="0.19 0.19 0.015" material="light_wood"/>
      <geom type="box" pos="0 -0.17 0.66" size="0.17 0.015 0.19" material="light_wood"/>
    </body>

    <!-- Sideboard / buffet against west wall -->
    <body name="sideboard" pos="0.3 8.5 0">
      <geom type="box" pos="0 0 0.4" size="0.25 0.7 0.4" material="oak_mat"/>
      <geom type="box" pos="0 0 0.81" size="0.25 0.7 0.01" material="oak_mat"/>
    </body>

    <!-- Plant in dining corner -->
    <body name="plant_dining" pos="0.5 5.5 0">
      <geom type="cylinder" pos="0 0 0.22" size="0.15 0.22" material="plant_pot"/>
      <geom type="sphere" pos="0 0 0.58" size="0.28" material="plant_leaf" contype="0" conaffinity="0"/>
    </body>


    <!-- ==================== KITCHEN (x=14..20, y=0..5) ==================== -->

    <!-- L-shaped counter (along east + south walls) -->
    <body name="counter_east" pos="19.6 2.5 0">
      <geom type="box" pos="0 0 0.44" size="0.35 2.3 0.44" material="counter_mat"/>
      <geom type="box" pos="0 0 0.90" size="0.38 2.3 0.015" material="counter_mat"/>
    </body>
    <body name="counter_south" pos="17 0.4 0">
      <geom type="box" pos="0 0 0.44" size="2.8 0.35 0.44" material="counter_mat"/>
      <geom type="box" pos="0 0 0.90" size="2.8 0.38 0.015" material="counter_mat"/>
    </body>

    <!-- Kitchen island -->
    <body name="island" pos="17 2.8 0">
      <geom type="box" pos="0 0 0.44" size="0.8 0.4 0.44" material="counter_mat"/>
      <geom type="box" pos="0 0 0.90" size="0.85 0.45 0.015" material="counter_mat"/>
    </body>

    <!-- Fridge (tall, against east wall near north) -->
    <body name="fridge" pos="19.5 4.3 0">
      <geom type="box" pos="0 0 0.9" size="0.38 0.38 0.9" material="steel_mat"/>
    </body>

    <!-- Bar stools at island -->
    <body name="stool1" pos="16.0 2.8 0">
      <geom type="cylinder" pos="0 0 0.35" size="0.16 0.35" material="dark_wood"/>
      <geom type="cylinder" pos="0 0 0.73" size="0.17 0.03" material="sofa_grey"/>
    </body>
    <body name="stool2" pos="18.0 2.8 0">
      <geom type="cylinder" pos="0 0 0.35" size="0.16 0.35" material="dark_wood"/>
      <geom type="cylinder" pos="0 0 0.73" size="0.17 0.03" material="sofa_grey"/>
    </body>


    <!-- ==================== STUDY (x=14..20, y=5..10) ==================== -->

    <!-- L-desk against east wall -->
    <body name="desk" pos="19.2 7.5 0">
      <geom type="box" pos="0 0 0.36" size="0.05 0.3 0.36" material="dark_wood"/>
      <geom type="box" pos="-0.6 0 0.36" size="0.05 0.3 0.36" material="dark_wood"/>
      <geom type="box" pos="-0.3 0 0.73" size="0.4 0.35 0.02" material="dark_wood"/>
      <!-- Monitor -->
      <geom type="box" pos="-0.3 0.18 0.95" size="0.28 0.02 0.20" material="black_mat"/>
      <geom type="box" pos="-0.3 0.12 0.78" size="0.06 0.06 0.04" material="black_mat"/>
      <!-- Keyboard -->
      <geom type="box" pos="-0.3 -0.05 0.76" size="0.18 0.06 0.01" material="black_mat"
            contype="0" conaffinity="0"/>
    </body>

    <!-- Desk chair (on wheels) -->
    <body name="desk_chair" pos="18.3 7.5 0">
      <geom type="cylinder" pos="0 0 0.22" size="0.25 0.02" material="black_mat"/>
      <geom type="cylinder" pos="0 0 0.35" size="0.04 0.12" material="black_mat"/>
      <geom type="box" pos="0 0 0.50" size="0.22 0.22 0.03" material="sofa_grey"/>
      <geom type="box" pos="0 0.20 0.72" size="0.20 0.03 0.20" material="sofa_grey"/>
    </body>

    <!-- Large bookshelf (against south wall of study) -->
    <body name="bookshelf" pos="17 5.3 0">
      <geom type="box" pos="0 0 1.0" size="1.2 0.18 1.0" material="shelf_mat"/>
      <geom type="box" pos="0 0 0.45" size="1.18 0.16 0.01" material="shelf_mat"/>
      <geom type="box" pos="0 0 0.90" size="1.18 0.16 0.01" material="shelf_mat"/>
      <geom type="box" pos="0 0 1.35" size="1.18 0.16 0.01" material="shelf_mat"/>
      <geom type="box" pos="0 0 1.80" size="1.18 0.16 0.01" material="shelf_mat"/>
    </body>

    <!-- Study rug -->
    <geom name="rug_study" type="box" pos="17.5 7.5 0.004" size="1.8 1.5 0.004"
          material="rug_blue" contype="0" conaffinity="0"/>

    <!-- Plant in study -->
    <body name="plant_study" pos="14.5 5.5 0">
      <geom type="cylinder" pos="0 0 0.3" size="0.18 0.3" material="plant_pot"/>
      <geom type="sphere" pos="0 0 0.72" size="0.32" material="plant_leaf" contype="0" conaffinity="0"/>
    </body>


    <!-- ==================== MASTER BEDROOM (x=0..7, y=10..14) ==================== -->

    <!-- Bed (king size, against west wall) -->
    <body name="master_bed" pos="1.5 12 0">
      <geom type="box" pos="0 0 0.18" size="1.0 0.85 0.18" material="bed_frame"/>
      <geom type="box" pos="0 0 0.40" size="0.95 0.80 0.06" material="bed_white"/>
      <geom type="box" pos="0 0 0.50" size="0.90 0.75 0.04" material="bed_blue"/>
      <geom type="box" pos="-0.65 -0.25 0.50" size="0.18 0.20 0.08" material="bed_white"/>
      <geom type="box" pos="-0.65 0.25 0.50" size="0.18 0.20 0.08" material="bed_white"/>
      <!-- Headboard -->
      <geom type="box" pos="-0.96 0 0.7" size="0.04 0.85 0.48" material="bed_frame"/>
    </body>

    <!-- Nightstands -->
    <body name="nightstand_l" pos="1.5 10.8 0">
      <geom type="box" pos="0 0 0.25" size="0.2 0.18 0.25" material="dark_wood"/>
      <geom type="box" pos="0 0 0.51" size="0.2 0.18 0.01" material="dark_wood"/>
    </body>
    <body name="nightstand_r" pos="1.5 13.2 0">
      <geom type="box" pos="0 0 0.25" size="0.2 0.18 0.25" material="dark_wood"/>
      <geom type="box" pos="0 0 0.51" size="0.2 0.18 0.01" material="dark_wood"/>
    </body>

    <!-- Wardrobe -->
    <body name="wardrobe" pos="5.5 13.5 0">
      <geom type="box" pos="0 0 1.05" size="1.0 0.3 1.05" material="dark_wood"/>
    </body>

    <!-- Bedroom rug -->
    <geom name="rug_master" type="box" pos="3 12 0.004" size="1.5 0.9 0.004"
          material="rug_beige" contype="0" conaffinity="0"/>


    <!-- ==================== GUEST BEDROOM (x=12..20, y=10..14) ==================== -->

    <!-- Bed -->
    <body name="guest_bed" pos="17.5 12.5 0">
      <geom type="box" pos="0 0 0.18" size="0.85 0.7 0.18" material="bed_frame"/>
      <geom type="box" pos="0 0 0.40" size="0.80 0.65 0.06" material="bed_white"/>
      <geom type="box" pos="0 0 0.50" size="0.75 0.60 0.04" material="bed_blue"/>
      <geom type="box" pos="0.81 0 0.65" size="0.04 0.70 0.42" material="bed_frame"/>
    </body>

    <!-- Guest nightstand -->
    <body name="guest_nightstand" pos="16.3 12.5 0">
      <geom type="box" pos="0 0 0.25" size="0.18 0.18 0.25" material="light_wood"/>
      <geom type="box" pos="0 0 0.51" size="0.18 0.18 0.01" material="light_wood"/>
    </body>

    <!-- Guest dresser -->
    <body name="dresser" pos="13 13.3 0">
      <geom type="box" pos="0 0 0.4" size="0.5 0.25 0.4" material="light_wood"/>
      <geom type="box" pos="0 0 0.81" size="0.5 0.25 0.01" material="light_wood"/>
    </body>


    <!-- ==================== BATHROOM (x=7..10, y=10..14) ==================== -->

    <!-- Bathtub (against north wall) -->
    <body name="bathtub" pos="8.5 13.2 0">
      <geom type="box" pos="0 0 0.30" size="0.65 0.35 0.30" material="ceramic_mat"/>
    </body>

    <!-- Sink vanity -->
    <body name="vanity" pos="7.5 11 0">
      <geom type="box" pos="0 0 0.40" size="0.35 0.25 0.40" material="counter_mat"/>
      <geom type="box" pos="0 0 0.81" size="0.35 0.28 0.01" material="counter_mat"/>
    </body>


    <!-- ==================== LAUNDRY NOOK (x=10..12, y=10..14) ==================== -->

    <!-- Washer -->
    <body name="washer" pos="11 11 0">
      <geom type="box" pos="0 0 0.42" size="0.35 0.35 0.42" material="steel_mat"/>
    </body>
    <!-- Dryer -->
    <body name="dryer" pos="11 12 0">
      <geom type="box" pos="0 0 0.42" size="0.35 0.35 0.42" material="steel_mat"/>
    </body>


    <!-- ==================== CENTRAL HALLWAY DECOR ==================== -->

    <!-- Console table against left wall of hallway -->
    <body name="console_table" pos="6.5 5 0">
      <geom type="box" pos="0 0 0.40" size="0.25 0.5 0.40" material="oak_mat"/>
      <geom type="box" pos="0 0 0.81" size="0.28 0.5 0.01" material="oak_mat"/>
    </body>

    <!-- Large potted plant near entry -->
    <body name="plant_entry" pos="8 1.5 0">
      <geom type="cylinder" pos="0 0 0.28" size="0.2 0.28" material="plant_pot"/>
      <geom type="sphere" pos="0 0 0.72" size="0.35" material="plant_leaf" contype="0" conaffinity="0"/>
    </body>

    <!-- Hallway runner rug -->
    <geom name="rug_hall" type="box" pos="10 5 0.004" size="0.5 3.5 0.004"
          material="rug_beige" contype="0" conaffinity="0"/>

    <!-- Hall plant near bedroom doors -->
    <body name="plant_hall" pos="12 9.5 0">
      <geom type="cylinder" pos="0 0 0.22" size="0.14 0.22" material="plant_pot"/>
      <geom type="sphere" pos="0 0 0.55" size="0.22" material="plant_leaf" contype="0" conaffinity="0"/>
    </body>

    <!-- Wall art in hallway -->
    <geom name="art_hall1" type="box" pos="6.02 3 1.5" size="0.015 0.35 0.25"
          material="painting_mat" contype="0" conaffinity="0"/>
    <geom name="art_hall2" type="box" pos="13.98 6.5 1.5" size="0.015 0.4 0.3"
          material="painting_mat" contype="0" conaffinity="0"/>

  

    <!-- === PERSON === -->
    <body name="person" pos="10.0 6.0 0.0" mocap="true">
  <!-- Torso: red capsule -->
  <geom name="person_torso" type="capsule" size="0.2 0.4"
        pos="0 0 1.0" rgba="0.8 0.2 0.2 1.0"
        contype="0" conaffinity="0" group="1"/>
  <!-- Head: skin-colored sphere -->
  <geom name="person_head" type="sphere" size="0.12"
        pos="0 0 1.55" rgba="0.9 0.7 0.6 1.0"
        contype="0" conaffinity="0" group="1"/>
  <!-- Left leg -->
  <geom name="person_leg_l" type="capsule" size="0.08 0.4"
        pos="0 0.1 0.4" rgba="0.2 0.2 0.6 1.0"
        contype="0" conaffinity="0" group="1"/>
  <!-- Right leg -->
  <geom name="person_leg_r" type="capsule" size="0.08 0.4"
        pos="0 -0.1 0.4" rgba="0.2 0.2 0.6 1.0"
        contype="0" conaffinity="0" group="1"/>
</body>

  </worldbody>
  <visual>
    <global offwidth="1280" offheight="720" />
  </visual>
  <default>
    <joint limited="true"/>
    <motor ctrllimited="true"/>
    <geom condim="4" contype="1" conaffinity="15" solref="0.001 2" friction="0.9 0.2 0.2"/>
    <equality solref="0.001 2"/>
    <default class="leg_joint_param">
      <joint damping="0.01" frictionloss="0.01" armature="0.01"/>
    </default>
  </default>
  <asset>
    <texture type="skybox" builtin="gradient" rgb1="0.3 0.5 0.7" rgb2="0.0 0.0 0.0" width="512" height="512" />
    <texture name="grid" type="2d" builtin="checker" rgb1="0.8 0.8 0.8" rgb2="0.6 0.6 0.6" width="256" height="256" />
    <material name="grid" texture="grid" texrepeat="8 8" reflectance="0.1" />
  
    <texture type="skybox" builtin="gradient" rgb1="0.88 0.90 0.95" rgb2="0.65 0.70 0.80"
             width="512" height="3072"/>

    <!-- Floor textures -->
    <texture type="2d" name="wood_tex" builtin="checker"
             rgb1="0.82 0.72 0.52" rgb2="0.72 0.62 0.42" width="200" height="200"/>
    <texture type="2d" name="tile_tex" builtin="checker"
             rgb1="0.90 0.90 0.88" rgb2="0.80 0.80 0.78" width="150" height="150"/>
    <texture type="2d" name="carpet_tex" builtin="flat"
             rgb1="0.50 0.52 0.56" rgb2="0.45 0.47 0.51" width="100" height="100"/>
    <texture type="2d" name="marble_tex" builtin="checker"
             rgb1="0.92 0.90 0.85" rgb2="0.85 0.82 0.77" width="120" height="120"/>
    <texture type="2d" name="bath_tex" builtin="checker"
             rgb1="0.85 0.90 0.92" rgb2="0.75 0.80 0.82" width="80" height="80"/>

    <material name="wood_mat" texture="wood_tex" texuniform="true" texrepeat="6 6" reflectance="0.12"/>
    <material name="tile_mat" texture="tile_tex" texuniform="true" texrepeat="8 8" reflectance="0.25"/>
    <material name="carpet_mat" texture="carpet_tex" texuniform="true" texrepeat="3 3" reflectance="0.02"/>
    <material name="marble_mat" texture="marble_tex" texuniform="true" texrepeat="10 12" reflectance="0.2"/>
    <material name="bath_tile" texture="bath_tex" texuniform="true" texrepeat="6 6" reflectance="0.3"/>

    <material name="wall_mat" rgba="0.93 0.93 0.91 1" reflectance="0.04"/>
    <material name="accent_wall" rgba="0.82 0.85 0.90 1" reflectance="0.04"/>

    <!-- Furniture -->
    <material name="dark_wood" rgba="0.35 0.22 0.12 1" reflectance="0.12"/>
    <material name="light_wood" rgba="0.70 0.55 0.38 1" reflectance="0.10"/>
    <material name="oak_mat" rgba="0.60 0.45 0.28 1" reflectance="0.10"/>
    <material name="sofa_blue" rgba="0.25 0.35 0.52 1" reflectance="0.04"/>
    <material name="sofa_grey" rgba="0.55 0.55 0.55 1" reflectance="0.04"/>
    <material name="cushion_mat" rgba="0.75 0.65 0.50 1" reflectance="0.03"/>
    <material name="bed_white" rgba="0.92 0.92 0.90 1" reflectance="0.03"/>
    <material name="bed_blue" rgba="0.30 0.40 0.58 1" reflectance="0.03"/>
    <material name="bed_frame" rgba="0.38 0.28 0.18 1" reflectance="0.08"/>
    <material name="counter_mat" rgba="0.75 0.75 0.72 1" reflectance="0.25"/>
    <material name="steel_mat" rgba="0.82 0.82 0.82 1" reflectance="0.40"/>
    <material name="black_mat" rgba="0.12 0.12 0.12 1" reflectance="0.50"/>
    <material name="shelf_mat" rgba="0.80 0.78 0.72 1" reflectance="0.10"/>
    <material name="ceramic_mat" rgba="0.95 0.93 0.88 1" reflectance="0.20"/>
    <material name="plant_pot" rgba="0.55 0.32 0.22 1" reflectance="0.05"/>
    <material name="plant_leaf" rgba="0.18 0.48 0.18 1" reflectance="0.03"/>
    <material name="rug_red" rgba="0.60 0.15 0.12 1" reflectance="0.02"/>
    <material name="rug_blue" rgba="0.15 0.25 0.45 1" reflectance="0.02"/>
    <material name="rug_beige" rgba="0.82 0.75 0.62 1" reflectance="0.02"/>
    <material name="lamp_shade" rgba="0.95 0.90 0.80 1" reflectance="0.01"/>
    <material name="lamp_base" rgba="0.70 0.65 0.55 1" reflectance="0.15"/>
    <material name="painting_mat" rgba="0.85 0.65 0.40 1" reflectance="0.05"/>
  
  </asset>
  <!-- IMU 传感器 -->
  <sensor>
    <framequat name="orientation" objtype="site" objname="imu"/>
    <gyro name="angular-velocity" site="imu"/>
  </sensor>

  <!-- Torque actuators: PD 在 Python 侧计算，和 Isaac Lab 训练一致 -->
  <!-- Dart 布局: [FR(h,t,c), FL(h,t,c), RR(h,t,c), RL(h,t,c), feet(4)] = 12+4 -->
  <actuator>
    <motor joint="fr_hip_joint"   name="fr_hip"   gear="1" ctrllimited="true" ctrlrange="-120 120"/>
    <motor joint="fr_thigh_joint" name="fr_thigh" gear="1" ctrllimited="true" ctrlrange="-120 120"/>
    <motor joint="fr_calf_joint"  name="fr_calf"  gear="1" ctrllimited="true" ctrlrange="-120 120"/>
    <motor joint="fl_hip_joint"   name="fl_hip"   gear="1" ctrllimited="true" ctrlrange="-120 120"/>
    <motor joint="fl_thigh_joint" name="fl_thigh" gear="1" ctrllimited="true" ctrlrange="-120 120"/>
    <motor joint="fl_calf_joint"  name="fl_calf"  gear="1" ctrllimited="true" ctrlrange="-120 120"/>
    <motor joint="rr_hip_joint"   name="rr_hip"   gear="1" ctrllimited="true" ctrlrange="-120 120"/>
    <motor joint="rr_thigh_joint" name="rr_thigh" gear="1" ctrllimited="true" ctrlrange="-120 120"/>
    <motor joint="rr_calf_joint"  name="rr_calf"  gear="1" ctrllimited="true" ctrlrange="-120 120"/>
    <motor joint="rl_hip_joint"   name="rl_hip"   gear="1" ctrllimited="true" ctrlrange="-120 120"/>
    <motor joint="rl_thigh_joint" name="rl_thigh" gear="1" ctrllimited="true" ctrlrange="-120 120"/>
    <motor joint="rl_calf_joint"  name="rl_calf"  gear="1" ctrllimited="true" ctrlrange="-120 120"/>
    <motor joint="fr_foot_joint"  name="fr_foot"  gear="1" ctrllimited="true" ctrlrange="-60 60"/>
    <motor joint="fl_foot_joint"  name="fl_foot"  gear="1" ctrllimited="true" ctrlrange="-60 60"/>
    <motor joint="rr_foot_joint"  name="rr_foot"  gear="1" ctrllimited="true" ctrlrange="-60 60"/>
    <motor joint="rl_foot_joint"  name="rl_foot"  gear="1" ctrllimited="true" ctrlrange="-60 60"/>
  </actuator>
</mujoco>